#VRML_SIM R2022b utf8

EXTERNPROTO "https://raw.githubusercontent.com/cyberbotics/webots/R2022b/projects/objects/backgrounds/protos/TexturedBackground.proto"
EXTERNPROTO "https://raw.githubusercontent.com/cyberbotics/webots/R2022b/projects/objects/backgrounds/protos/TexturedBackgroundLight.proto"
EXTERNPROTO "https://raw.githubusercontent.com/cyberbotics/webots/R2022b/projects/objects/floors/protos/RectangleArena.proto"

WorldInfo {
  info [
    "Example use of a spherical Camera device."
  ]
  title "Spherical Camera"
}
Viewpoint {
  orientation 0.008391408959148356 0.9996317362366726 0.025806513986507032 1.2174840005390608
  position -0.6106801720011082 0.015262585987470403 1.8202934524582195
}
TexturedBackground {
}
TexturedBackgroundLight {
}
RectangleArena {
}
DEF GREEN_OBJECT Solid {
  translation -0.21473646 -0.43026667 0.05
  rotation 0.0026909805133862965 -0.0026909805133862965 -0.9999927585976576 1.5708
  children [
    DEF BOX_SHAPE Shape {
      appearance PBRAppearance {
        baseColor 0 1 0
        roughness 0.2189099510000001
        metalness 0
      }
      geometry Box {
        size 0.1 0.23 0.1
      }
    }
  ]
  name "green object"
  boundingObject USE BOX_SHAPE
}
DEF BLUE_OBJECT Solid {
  translation 0.393343 -0.199452 0.07
  rotation -0.45854819001874086 -0.6283842603974643 -0.6283842603974643 -2.281714
  children [
    DEF SPHERE_SHAPE Shape {
      appearance PBRAppearance {
        baseColor 0 0 1
        roughness 0.519341125
        metalness 0
      }
      geometry Sphere {
        radius 0.07
        subdivision 2
      }
    }
  ]
  name "blue object"
  boundingObject USE SPHERE_SHAPE
}
DEF PINK_OBJECT Solid {
  translation 0.0630102 0.210413 0.05
  rotation 0.7071067811865476 0.7071067811865476 0 3.14159
  children [
    DEF CYLINDER_SHAPE Shape {
      appearance PBRAppearance {
        baseColor 1 0.1 0.3
        roughness 0.16827074099999995
        metalness 0
      }
      geometry Cylinder {
        height 0.1
        radius 0.1
        subdivision 20
      }
    }
  ]
  name "pink object"
  boundingObject USE CYLINDER_SHAPE
}
Robot {
  translation -0.3564797016475661 0.2196458126008719 -0.00022597410797549344
  rotation -0.014287997381916098 0.016083623913317073 0.9997685583036853 1.4529019514000663
  children [
    Transform {
      translation 0 0 0.0415
      rotation 0 0 1 -1.570796
      children [
        Shape {
          appearance PBRAppearance {
            baseColor 0.74902 0.74902 0.74902
            roughness 1
            metalness 0
          }
          geometry DEF BODY Cylinder {
            height 0.08
            radius 0.045
          }
        }
      ]
    }
    HingeJoint {
      jointParameters HingeJointParameters {
        position 11674.416030502895
        axis 0 1 0
        anchor 0 0 0.025
      }
      device [
        RotationalMotor {
          name "left wheel motor"
          consumptionFactor 70
        }
        PositionSensor {
          name "left wheel sensor"
        }
      ]
      endPoint Solid {
        translation 0 0.045000000000000005 0.025
        rotation 0.0072749319477531564 -0.00727489815523283 -0.9999470742104237 1.5708489931922733
        children [
          DEF WHEEL Transform {
            rotation 0.577656895078166 0.5771968951617173 -0.5771968951617173 -2.093935
            children [
              Shape {
                appearance PBRAppearance {
                  baseColor 0.301961 0.301961 0.301961
                  roughness 1
                  metalness 0
                }
                geometry Cylinder {
                  height 0.01
                  radius 0.025
                }
              }
            ]
          }
        ]
        name "left wheel"
        boundingObject USE WHEEL
        physics DEF PHYSICS_WHEEL Physics {
          density -1
          mass 0.05
        }
        linearVelocity 0.008838524462651 0.0744768814633726 8.720469466580193e-09
        angularVelocity -2.9790908764486925 0.3535499865973225 2.7011530694030665e-06
      }
    }
    HingeJoint {
      jointParameters HingeJointParameters {
        position 9156.577267030892
        axis 0 1 0
        anchor 0 0 0.025
      }
      device [
        RotationalMotor {
          name "right wheel motor"
          consumptionFactor 70
        }
        PositionSensor {
          name "right wheel sensor"
        }
      ]
      endPoint Solid {
        translation 0 -0.045 0.025
        rotation 0.65539757518867 -0.6553975191159778 0.37537729070021447 3.85979539810063
        children [
          USE WHEEL
        ]
        name "right wheel"
        boundingObject USE WHEEL
        physics USE PHYSICS_WHEEL
        linearVelocity 0.008838564973686206 0.07447722143643881 -6.950090934793066e-08
        angularVelocity -2.979090936153808 0.35354962856680106 1.8023350277928652e-06
      }
    }
    DEF US0 DistanceSensor {
      translation 0.042 0.02 0.063
      rotation 0 0 -1 -0.499205
      children [
        DEF SONAR_SENSOR Transform {
          rotation 0.577656895078166 0.5771968951617173 -0.5771968951617173 -2.093935
          children [
            Shape {
              appearance PBRAppearance {
                baseColor 0.301961 0.301961 0.301961
                roughness 1
                metalness 0
              }
              geometry Cylinder {
                height 0.004
                radius 0.008
              }
            }
          ]
        }
      ]
      name "us0"
      lookupTable [
        0 0.7 0
        0.2 0 0
      ]
      type "sonar"
      numberOfRays 20
    }
    DEF US1 DistanceSensor {
      translation 0.042 -0.02 0.063
      rotation 0 0 1 -0.500795
      children [
        USE SONAR_SENSOR
      ]
      name "us1"
      lookupTable [
        0 0.7 0
        0.2 0 0
      ]
      type "sonar"
      numberOfRays 20
    }
    DEF SPHERICAL_CAMERA Camera {
      translation 0 0 0.15
      rotation 0 1 0 1.5708
      children [
        DEF LENS Shape {
          appearance PBRAppearance {
            baseColor 0 0 0
            roughness 1.1102230246251565e-16
            metalness 0
          }
          geometry Sphere {
            radius 0.005
            subdivision 2
          }
        }
        DEF STRUCTURE_AXES Shape {
          appearance Appearance {
            material Material {
              diffuseColor 0.02 0.02 0.02
            }
          }
          geometry IndexedLineSet {
            coord Coordinate {
              point [
                -0.01 0 0
                0.08 -0.01 0
                0.08 0.01 0
                0.08 0 0.01
                0.08 0 -0.01
              ]
            }
            coordIndex [
              0, 1, 0, 2, 0, 3, 0, 4
            ]
          }
        }
        DEF CAMERA_SHAPE Transform {
          translation -0.01 0 0
          rotation 0 1 0 1.5708
          children [
            DEF CAMERA_OUTLINE Shape {
              appearance PBRAppearance {
                baseColor 0.898039 0.898039 0.898039
                roughness 1
                metalness 0
              }
              geometry Cylinder {
                height 0.02
                radius 0.008
              }
            }
          ]
        }
      ]
      fieldOfView 3.1415
      width 128
      height 128
      spherical TRUE
      antiAliasing TRUE
    }
    DEF SMILE Transform {
      translation 0.036 0 0.025
      rotation 0.25056300542381216 -0.9351130202419243 -0.25056300542381216 1.637834
      children [
        Shape {
          appearance PBRAppearance {
            baseColor 0.301961 0.301961 0.301961
            roughness 1
            metalness 0
          }
          geometry Cylinder {
            height 0.018
            radius 0.009
            subdivision 3
          }
        }
      ]
    }
  ]
  name "MyBot"
  boundingObject Transform {
    translation 0 0 0.0415
    rotation 0 0 1 -1.570796
    children [
      USE BODY
    ]
  }
  physics Physics {
    density -1
    mass 0.5
    centerOfMass [
      0 0 0.05
    ]
  }
  controller "spherical_camera"
  linearVelocity 0.00883855491577865 0.07447696772671017 -2.9267809906776176e-08
  angularVelocity 3.387878012935035e-06 4.900342701791881e-07 3.004822843039843e-06
}
